[rospy.client][INFO] 2021-01-09 04:16:25,247: init_node, name[/train_3133_1610165785233], pid[3133]
[xmlrpc][INFO] 2021-01-09 04:16:25,248: XML-RPC server binding to 0.0.0.0:0
[xmlrpc][INFO] 2021-01-09 04:16:25,248: Started XML-RPC server [http://192.168.0.162:42947/]
[rospy.init][INFO] 2021-01-09 04:16:25,248: ROS Slave URI: [http://192.168.0.162:42947/]
[rospy.impl.masterslave][INFO] 2021-01-09 04:16:25,248: _ready: http://192.168.0.162:42947/
[rospy.registration][INFO] 2021-01-09 04:16:25,248: Registering with master node http://192.168.0.201:11311
[xmlrpc][INFO] 2021-01-09 04:16:25,248: xml rpc node: starting XML-RPC server
[rospy.init][INFO] 2021-01-09 04:16:25,348: registered with master
[rospy.rosout][INFO] 2021-01-09 04:16:25,348: initializing /rosout core topic
[rospy.rosout][INFO] 2021-01-09 04:16:25,354: connected to core topic /rosout
[rospy.simtime][INFO] 2021-01-09 04:16:25,356: /use_sim_time is not set, will not subscribe to simulated time [/clock] topic
[rospy.internal][INFO] 2021-01-09 04:16:25,373: topic[/bev/temporal_bev_image] adding connection to [http://192.168.0.201:42461/], count 0
[rospy.internal][INFO] 2021-01-09 04:16:25,375: topic[/is_start_episode] adding connection to [http://192.168.0.201:45929/], count 0
[rospy.internal][INFO] 2021-01-09 04:16:25,380: topic[/scan] adding connection to [http://192.168.0.201:34577/], count 0
[rospy.internal][INFO] 2021-01-09 04:16:25,384: topic[/start_goal_points] adding connection to [http://192.168.0.201:42155/], count 0
[rospy.internal][INFO] 2021-01-09 04:16:25,384: topic[/scan] adding connection to [http://192.168.0.201:35655/], count 1
[rospy.internal][INFO] 2021-01-09 04:16:25,386: topic[/odom] adding connection to [http://192.168.0.201:34577/], count 0
[rospy.internal][INFO] 2021-01-09 04:16:25,501: topic[/episode_watcher/is_finish_episode] adding connection to [/episode_manager], count 0
[rospy.internal][INFO] 2021-01-09 04:16:25,599: topic[/rosout] adding connection to [/rosout], count 0
[rospy.internal][INFO] 2021-01-09 04:16:25,599: topic[/cmd_vel] adding connection to [/gazebo], count 0
[rospy.internal][WARNING] 2021-01-09 04:35:29,270: Unknown error initiating TCP/IP socket to 192.168.0.201:37267 (http://192.168.0.201:42461/): Traceback (most recent call last):
  File "/opt/ros/noetic/lib/python3/dist-packages/rospy/impl/tcpros_base.py", line 562, in connect
    self.read_header()
  File "/opt/ros/noetic/lib/python3/dist-packages/rospy/impl/tcpros_base.py", line 657, in read_header
    self._validate_header(read_ros_handshake_header(sock, self.read_buff, self.protocol.buff_size))
  File "/opt/ros/noetic/lib/python3/dist-packages/rosgraph/network.py", line 357, in read_ros_handshake_header
    d = sock.recv(buff_size)
ConnectionResetError: [Errno 104] Connection reset by peer

[rospy.internal][INFO] 2021-01-09 04:35:29,270: topic[/bev/temporal_bev_image] removing connection to http://192.168.0.201:42461/
[rospy.internal][WARNING] 2021-01-09 04:35:30,111: Unknown error initiating TCP/IP socket to 192.168.0.201:50861 (http://192.168.0.201:35655/): Traceback (most recent call last):
  File "/opt/ros/noetic/lib/python3/dist-packages/rospy/impl/tcpros_base.py", line 562, in connect
    self.read_header()
  File "/opt/ros/noetic/lib/python3/dist-packages/rospy/impl/tcpros_base.py", line 657, in read_header
    self._validate_header(read_ros_handshake_header(sock, self.read_buff, self.protocol.buff_size))
  File "/opt/ros/noetic/lib/python3/dist-packages/rosgraph/network.py", line 357, in read_ros_handshake_header
    d = sock.recv(buff_size)
ConnectionResetError: [Errno 104] Connection reset by peer

[rospy.internal][INFO] 2021-01-09 04:35:30,111: topic[/scan] removing connection to http://192.168.0.201:35655/
[rospy.internal][INFO] 2021-01-09 04:35:32,723: topic[/bev/temporal_bev_image] adding connection to [http://192.168.0.201:45647/], count 0
[rospy.internal][INFO] 2021-01-09 04:35:32,729: topic[/scan] adding connection to [http://192.168.0.201:38065/], count 1
[rospy.internal][WARNING] 2021-01-09 04:36:12,975: Unknown error initiating TCP/IP socket to 192.168.0.201:58247 (http://192.168.0.201:45647/): Traceback (most recent call last):
  File "/opt/ros/noetic/lib/python3/dist-packages/rospy/impl/tcpros_base.py", line 562, in connect
    self.read_header()
  File "/opt/ros/noetic/lib/python3/dist-packages/rospy/impl/tcpros_base.py", line 657, in read_header
    self._validate_header(read_ros_handshake_header(sock, self.read_buff, self.protocol.buff_size))
  File "/opt/ros/noetic/lib/python3/dist-packages/rosgraph/network.py", line 357, in read_ros_handshake_header
    d = sock.recv(buff_size)
ConnectionResetError: [Errno 104] Connection reset by peer

[rospy.internal][INFO] 2021-01-09 04:36:12,975: topic[/bev/temporal_bev_image] removing connection to http://192.168.0.201:45647/
[rospy.internal][WARNING] 2021-01-09 04:36:12,984: Unknown error initiating TCP/IP socket to 192.168.0.201:55231 (http://192.168.0.201:38065/): Traceback (most recent call last):
  File "/opt/ros/noetic/lib/python3/dist-packages/rospy/impl/tcpros_base.py", line 562, in connect
    self.read_header()
  File "/opt/ros/noetic/lib/python3/dist-packages/rospy/impl/tcpros_base.py", line 657, in read_header
    self._validate_header(read_ros_handshake_header(sock, self.read_buff, self.protocol.buff_size))
  File "/opt/ros/noetic/lib/python3/dist-packages/rosgraph/network.py", line 357, in read_ros_handshake_header
    d = sock.recv(buff_size)
ConnectionResetError: [Errno 104] Connection reset by peer

[rospy.internal][INFO] 2021-01-09 04:36:12,985: topic[/scan] removing connection to http://192.168.0.201:38065/
[rospy.internal][INFO] 2021-01-09 04:36:36,298: topic[/bev/temporal_bev_image] adding connection to [http://192.168.0.201:38531/], count 0
[rospy.internal][INFO] 2021-01-09 04:36:36,303: topic[/scan] adding connection to [http://192.168.0.201:36571/], count 1
[rospy.internal][WARNING] 2021-01-09 04:39:58,435: Unknown error initiating TCP/IP socket to 192.168.0.201:51333 (http://192.168.0.201:38531/): Traceback (most recent call last):
  File "/opt/ros/noetic/lib/python3/dist-packages/rospy/impl/tcpros_base.py", line 562, in connect
    self.read_header()
  File "/opt/ros/noetic/lib/python3/dist-packages/rospy/impl/tcpros_base.py", line 657, in read_header
    self._validate_header(read_ros_handshake_header(sock, self.read_buff, self.protocol.buff_size))
  File "/opt/ros/noetic/lib/python3/dist-packages/rosgraph/network.py", line 357, in read_ros_handshake_header
    d = sock.recv(buff_size)
ConnectionResetError: [Errno 104] Connection reset by peer

[rospy.internal][INFO] 2021-01-09 04:39:58,435: topic[/bev/temporal_bev_image] removing connection to http://192.168.0.201:38531/
[rospy.internal][WARNING] 2021-01-09 04:39:59,222: Unknown error initiating TCP/IP socket to 192.168.0.201:39881 (http://192.168.0.201:36571/): Traceback (most recent call last):
  File "/opt/ros/noetic/lib/python3/dist-packages/rospy/impl/tcpros_base.py", line 562, in connect
    self.read_header()
  File "/opt/ros/noetic/lib/python3/dist-packages/rospy/impl/tcpros_base.py", line 657, in read_header
    self._validate_header(read_ros_handshake_header(sock, self.read_buff, self.protocol.buff_size))
  File "/opt/ros/noetic/lib/python3/dist-packages/rosgraph/network.py", line 357, in read_ros_handshake_header
    d = sock.recv(buff_size)
ConnectionResetError: [Errno 104] Connection reset by peer

[rospy.internal][INFO] 2021-01-09 04:39:59,223: topic[/scan] removing connection to http://192.168.0.201:36571/
[rospy.core][INFO] 2021-01-09 04:40:16,355: signal_shutdown [signal-2]
[rospy.internal][INFO] 2021-01-09 04:40:16,363: topic[/rosout] removing connection to /rosout
[rospy.internal][INFO] 2021-01-09 04:40:16,363: topic[/cmd_vel] removing connection to /gazebo
[rospy.internal][INFO] 2021-01-09 04:40:16,364: topic[/episode_watcher/is_finish_episode] removing connection to /episode_manager
[rospy.internal][INFO] 2021-01-09 04:40:16,364: topic[/odom] removing connection to http://192.168.0.201:34577/
[rospy.internal][WARNING] 2021-01-09 04:40:16,365: Unknown error initiating TCP/IP socket to 192.168.0.201:47923 (http://192.168.0.201:34577/): Traceback (most recent call last):
  File "/opt/ros/noetic/lib/python3/dist-packages/rospy/impl/tcpros_base.py", line 563, in connect
    self.local_endpoint = self.socket.getsockname()
AttributeError: 'NoneType' object has no attribute 'getsockname'

[rospy.internal][INFO] 2021-01-09 04:40:16,365: topic[/start_goal_points] removing connection to http://192.168.0.201:42155/
[rospy.internal][INFO] 2021-01-09 04:40:16,366: topic[/scan] removing connection to http://192.168.0.201:34577/
[rospy.internal][INFO] 2021-01-09 04:40:16,366: topic[/is_start_episode] removing connection to http://192.168.0.201:45929/
[rospy.impl.masterslave][INFO] 2021-01-09 04:40:16,366: signal-2
[rospy.internal][WARNING] 2021-01-09 04:40:16,367: Unknown error initiating TCP/IP socket to 192.168.0.201:47923 (http://192.168.0.201:34577/): Traceback (most recent call last):
  File "/opt/ros/noetic/lib/python3/dist-packages/rospy/impl/tcpros_base.py", line 562, in connect
    self.read_header()
  File "/opt/ros/noetic/lib/python3/dist-packages/rospy/impl/tcpros_base.py", line 657, in read_header
    self._validate_header(read_ros_handshake_header(sock, self.read_buff, self.protocol.buff_size))
AttributeError: 'NoneType' object has no attribute 'buff_size'

[rospy.core][INFO] 2021-01-09 04:40:16,853: signal_shutdown [signal-2]
[rospy.core][INFO] 2021-01-09 04:40:16,886: signal_shutdown [signal-2]
[rospy.core][INFO] 2021-01-09 04:40:16,921: signal_shutdown [signal-2]
[rospy.core][INFO] 2021-01-09 04:40:16,947: signal_shutdown [signal-2]
[rospy.core][INFO] 2021-01-09 04:40:16,974: signal_shutdown [signal-2]
[rospy.core][INFO] 2021-01-09 04:40:17,064: signal_shutdown [signal-2]
[rospy.core][INFO] 2021-01-09 04:40:17,066: signal_shutdown [signal-2]
[rospy.core][INFO] 2021-01-09 04:40:17,075: signal_shutdown [atexit]
