[rospy.client][INFO] 2020-12-07 09:34:59,323: init_node, name[/train_524_1607333699291], pid[524]
[xmlrpc][INFO] 2020-12-07 09:34:59,324: XML-RPC server binding to 0.0.0.0:0
[xmlrpc][INFO] 2020-12-07 09:34:59,324: Started XML-RPC server [http://192.168.0.191:45761/]
[rospy.init][INFO] 2020-12-07 09:34:59,325: ROS Slave URI: [http://192.168.0.191:45761/]
[rospy.impl.masterslave][INFO] 2020-12-07 09:34:59,325: _ready: http://192.168.0.191:45761/
[rospy.registration][INFO] 2020-12-07 09:34:59,327: Registering with master node http://192.168.0.201:11311
[xmlrpc][INFO] 2020-12-07 09:34:59,327: xml rpc node: starting XML-RPC server
[rospy.init][INFO] 2020-12-07 09:34:59,426: registered with master
[rospy.rosout][INFO] 2020-12-07 09:34:59,426: initializing /rosout core topic
[rospy.rosout][INFO] 2020-12-07 09:34:59,431: connected to core topic /rosout
[rospy.simtime][INFO] 2020-12-07 09:34:59,432: /use_sim_time is not set, will not subscribe to simulated time [/clock] topic
[rospy.internal][INFO] 2020-12-07 09:34:59,451: topic[/bev/flow_array_x] adding connection to [http://192.168.0.201:36049/], count 0
[rospy.internal][INFO] 2020-12-07 09:34:59,462: topic[/scan] adding connection to [http://192.168.0.201:45983/], count 0
[rospy.internal][INFO] 2020-12-07 09:34:59,463: topic[/scan] adding connection to [http://192.168.0.201:33281/], count 1
[rospy.internal][INFO] 2020-12-07 09:34:59,471: topic[/is_start_episode] adding connection to [http://192.168.0.201:44577/], count 0
[rospy.internal][INFO] 2020-12-07 09:34:59,474: topic[/odom] adding connection to [http://192.168.0.201:33281/], count 0
[rospy.internal][INFO] 2020-12-07 09:34:59,475: topic[/start_goal_points] adding connection to [http://192.168.0.201:39321/], count 0
[rospy.internal][INFO] 2020-12-07 09:34:59,477: topic[/bev/raycast_image] adding connection to [http://192.168.0.201:37487/], count 0
[rospy.internal][INFO] 2020-12-07 09:34:59,480: topic[/bev/flow_array_y] adding connection to [http://192.168.0.201:36049/], count 0
[rospy.internal][ERROR] 2020-12-07 09:34:59,482: Unable to initiate TCP/IP socket to 192.168.0.201:44725 (http://192.168.0.201:36049/): Traceback (most recent call last):
  File "/opt/ros/noetic/lib/python3/dist-packages/rospy/impl/tcpros_base.py", line 562, in connect
    self.read_header()
  File "/opt/ros/noetic/lib/python3/dist-packages/rospy/impl/tcpros_base.py", line 657, in read_header
    self._validate_header(read_ros_handshake_header(sock, self.read_buff, self.protocol.buff_size))
  File "/opt/ros/noetic/lib/python3/dist-packages/rospy/impl/tcpros_base.py", line 600, in _validate_header
    raise TransportInitError("remote error reported: %s"%header['error'])
rospy.exceptions.TransportInitError: remote error reported: Client [/train_524_1607333699291] wants topic /bev/flow_array_y to have datatype/md5sum [sensor_msgs/Image/060021388200f6f0f447d0fcd9c64743], but our version has [std_msgs/Float32MultiArray/6a40e0ffa6a17a503ac3f8616991b1f6]. Dropping connection.

[rospy.internal][ERROR] 2020-12-07 09:34:59,482: unable to create subscriber transport: remote error reported: Client [/train_524_1607333699291] wants topic /bev/flow_array_y to have datatype/md5sum [sensor_msgs/Image/060021388200f6f0f447d0fcd9c64743], but our version has [std_msgs/Float32MultiArray/6a40e0ffa6a17a503ac3f8616991b1f6]. Dropping connection..  Will try again in 0.5s
[rospy.internal][INFO] 2020-12-07 09:34:59,613: topic[/cmd_vel] adding connection to [/gazebo], count 0
[rospy.internal][INFO] 2020-12-07 09:34:59,614: topic[/episode_watcher/is_finish_episode] adding connection to [/episode_manager], count 0
[rospy.internal][INFO] 2020-12-07 09:34:59,712: topic[/rosout] adding connection to [/rosout], count 0
[rospy.internal][ERROR] 2020-12-07 09:35:00,486: Unable to initiate TCP/IP socket to 192.168.0.201:44725 (http://192.168.0.201:36049/): Traceback (most recent call last):
  File "/opt/ros/noetic/lib/python3/dist-packages/rospy/impl/tcpros_base.py", line 562, in connect
    self.read_header()
  File "/opt/ros/noetic/lib/python3/dist-packages/rospy/impl/tcpros_base.py", line 657, in read_header
    self._validate_header(read_ros_handshake_header(sock, self.read_buff, self.protocol.buff_size))
  File "/opt/ros/noetic/lib/python3/dist-packages/rospy/impl/tcpros_base.py", line 600, in _validate_header
    raise TransportInitError("remote error reported: %s"%header['error'])
rospy.exceptions.TransportInitError: remote error reported: Client [/train_524_1607333699291] wants topic /bev/flow_array_y to have datatype/md5sum [sensor_msgs/Image/060021388200f6f0f447d0fcd9c64743], but our version has [std_msgs/Float32MultiArray/6a40e0ffa6a17a503ac3f8616991b1f6]. Dropping connection.

[rospy.internal][ERROR] 2020-12-07 09:35:01,489: Unable to initiate TCP/IP socket to 192.168.0.201:44725 (http://192.168.0.201:36049/): Traceback (most recent call last):
  File "/opt/ros/noetic/lib/python3/dist-packages/rospy/impl/tcpros_base.py", line 562, in connect
    self.read_header()
  File "/opt/ros/noetic/lib/python3/dist-packages/rospy/impl/tcpros_base.py", line 657, in read_header
    self._validate_header(read_ros_handshake_header(sock, self.read_buff, self.protocol.buff_size))
  File "/opt/ros/noetic/lib/python3/dist-packages/rospy/impl/tcpros_base.py", line 600, in _validate_header
    raise TransportInitError("remote error reported: %s"%header['error'])
rospy.exceptions.TransportInitError: remote error reported: Client [/train_524_1607333699291] wants topic /bev/flow_array_y to have datatype/md5sum [sensor_msgs/Image/060021388200f6f0f447d0fcd9c64743], but our version has [std_msgs/Float32MultiArray/6a40e0ffa6a17a503ac3f8616991b1f6]. Dropping connection.

[rospy.internal][ERROR] 2020-12-07 09:35:03,492: Unable to initiate TCP/IP socket to 192.168.0.201:44725 (http://192.168.0.201:36049/): Traceback (most recent call last):
  File "/opt/ros/noetic/lib/python3/dist-packages/rospy/impl/tcpros_base.py", line 562, in connect
    self.read_header()
  File "/opt/ros/noetic/lib/python3/dist-packages/rospy/impl/tcpros_base.py", line 657, in read_header
    self._validate_header(read_ros_handshake_header(sock, self.read_buff, self.protocol.buff_size))
  File "/opt/ros/noetic/lib/python3/dist-packages/rospy/impl/tcpros_base.py", line 600, in _validate_header
    raise TransportInitError("remote error reported: %s"%header['error'])
rospy.exceptions.TransportInitError: remote error reported: Client [/train_524_1607333699291] wants topic /bev/flow_array_y to have datatype/md5sum [sensor_msgs/Image/060021388200f6f0f447d0fcd9c64743], but our version has [std_msgs/Float32MultiArray/6a40e0ffa6a17a503ac3f8616991b1f6]. Dropping connection.

[rospy.core][INFO] 2020-12-07 09:35:03,502: signal_shutdown [signal-2]
[rospy.internal][INFO] 2020-12-07 09:35:03,507: topic[/rosout] removing connection to /rosout
[rospy.internal][INFO] 2020-12-07 09:35:03,508: topic[/cmd_vel] removing connection to /gazebo
[rospy.internal][INFO] 2020-12-07 09:35:03,508: topic[/episode_watcher/is_finish_episode] removing connection to /episode_manager
[rospy.internal][INFO] 2020-12-07 09:35:03,508: topic[/bev/flow_array_x] removing connection to http://192.168.0.201:36049/
[rospy.internal][INFO] 2020-12-07 09:35:03,509: topic[/bev/flow_array_y] removing connection to http://192.168.0.201:36049/
[rospy.internal][INFO] 2020-12-07 09:35:03,509: topic[/bev/raycast_image] removing connection to http://192.168.0.201:37487/
[rospy.internal][INFO] 2020-12-07 09:35:03,510: topic[/odom] removing connection to http://192.168.0.201:33281/
[rospy.internal][WARNING] 2020-12-07 09:35:03,510: Unknown error initiating TCP/IP socket to 192.168.0.201:52859 (http://192.168.0.201:37487/): Traceback (most recent call last):
  File "/opt/ros/noetic/lib/python3/dist-packages/rospy/impl/tcpros_base.py", line 562, in connect
    self.read_header()
  File "/opt/ros/noetic/lib/python3/dist-packages/rospy/impl/tcpros_base.py", line 657, in read_header
    self._validate_header(read_ros_handshake_header(sock, self.read_buff, self.protocol.buff_size))
AttributeError: 'NoneType' object has no attribute 'buff_size'

[rospy.internal][INFO] 2020-12-07 09:35:03,511: topic[/start_goal_points] removing connection to http://192.168.0.201:39321/
[rospy.internal][WARNING] 2020-12-07 09:35:03,511: Unknown error initiating TCP/IP socket to 192.168.0.201:55471 (http://192.168.0.201:39321/): Traceback (most recent call last):
  File "/opt/ros/noetic/lib/python3/dist-packages/rospy/impl/tcpros_base.py", line 562, in connect
    self.read_header()
  File "/opt/ros/noetic/lib/python3/dist-packages/rospy/impl/tcpros_base.py", line 657, in read_header
    self._validate_header(read_ros_handshake_header(sock, self.read_buff, self.protocol.buff_size))
AttributeError: 'NoneType' object has no attribute 'buff_size'

[rospy.internal][INFO] 2020-12-07 09:35:03,512: topic[/scan] removing connection to http://192.168.0.201:45983/
[rospy.internal][INFO] 2020-12-07 09:35:03,512: topic[/scan] removing connection to http://192.168.0.201:33281/
[rospy.internal][WARNING] 2020-12-07 09:35:03,513: Unknown error initiating TCP/IP socket to 192.168.0.201:55505 (http://192.168.0.201:45983/): Traceback (most recent call last):
  File "/opt/ros/noetic/lib/python3/dist-packages/rospy/impl/tcpros_base.py", line 562, in connect
    self.read_header()
  File "/opt/ros/noetic/lib/python3/dist-packages/rospy/impl/tcpros_base.py", line 657, in read_header
    self._validate_header(read_ros_handshake_header(sock, self.read_buff, self.protocol.buff_size))
AttributeError: 'NoneType' object has no attribute 'buff_size'

[rospy.internal][INFO] 2020-12-07 09:35:03,513: topic[/is_start_episode] removing connection to http://192.168.0.201:44577/
[rospy.impl.masterslave][INFO] 2020-12-07 09:35:03,513: signal-2
[rospy.internal][WARNING] 2020-12-07 09:35:03,514: Unknown error initiating TCP/IP socket to 192.168.0.201:36907 (http://192.168.0.201:44577/): Traceback (most recent call last):
  File "/opt/ros/noetic/lib/python3/dist-packages/rospy/impl/tcpros_base.py", line 563, in connect
    self.local_endpoint = self.socket.getsockname()
AttributeError: 'NoneType' object has no attribute 'getsockname'

[rospy.internal][WARNING] 2020-12-07 09:35:03,515: Unknown error initiating TCP/IP socket to 192.168.0.201:53505 (http://192.168.0.201:33281/): Traceback (most recent call last):
  File "/opt/ros/noetic/lib/python3/dist-packages/rospy/impl/tcpros_base.py", line 562, in connect
    self.read_header()
  File "/opt/ros/noetic/lib/python3/dist-packages/rospy/impl/tcpros_base.py", line 657, in read_header
    self._validate_header(read_ros_handshake_header(sock, self.read_buff, self.protocol.buff_size))
AttributeError: 'NoneType' object has no attribute 'buff_size'

[rospy.core][INFO] 2020-12-07 09:35:04,002: signal_shutdown [signal-2]
[rospy.core][INFO] 2020-12-07 09:35:04,033: signal_shutdown [signal-2]
[rospy.core][INFO] 2020-12-07 09:35:04,063: signal_shutdown [signal-2]
[rospy.core][INFO] 2020-12-07 09:35:04,093: signal_shutdown [signal-2]
[rospy.core][INFO] 2020-12-07 09:35:04,131: signal_shutdown [signal-2]
[rospy.core][INFO] 2020-12-07 09:35:04,155: signal_shutdown [signal-2]
[rospy.core][INFO] 2020-12-07 09:35:04,170: signal_shutdown [atexit]
